<?xml version="1.0" encoding="utf-8"?>
<!-- This URDF was automatically created by SolidWorks to URDF Exporter! Originally created by Stephen Brawner (brawner@gmail.com) 
     Commit Version: 1.6.0-4-g7f85cfe  Build Version: 1.6.7995.38578
     For more information, please see http://wiki.ros.org/sw_urdf_exporter -->
<robot
  name="robot_simulation">
  <link name="base_footprint">
  </link>

  <link
    name="base_link">
    <inertial>
      <origin
        xyz="-0.043142014768968 1.11567242370519E-17 0.0221789927693677"
        rpy="0 0 0" />
      <mass
        value="0.0926673491878989" />
      <inertia
        ixx="1.53222325318173E-05"
        ixy="-1.90046743127107E-11"
        ixz="-1.2127406767521E-20"
        iyy="0.000102600033510016"
        iyz="1.0498279805204E-20"
        izz="0.000111817073657985" />
    </inertial>
    <visual>
      <origin
        xyz="0 0 0"
        rpy="0 0 0" />
      <geometry>
        <mesh
          filename="package://robot_simulation/meshes_robot2/base_link.STL" />
      </geometry>
      <material
        name="">
        <color
          rgba="1 1 1 1" />
      </material>
    </visual>
    <collision>
      <origin
        xyz="0 0 0"
        rpy="0 0 0" />
      <geometry>
        <mesh
          filename="package://robot_simulation/meshes_robot2/base_link.STL" />
      </geometry>
    </collision>
  </link>
  <link
    name="Link_r">
    <inertial>
      <origin
        xyz="-0.0544999999999969 -4.71844785465692E-16 1.70002900645727E-15"
        rpy="0 0 0" />
      <mass
        value="2.8831968742214" />
      <inertia
        ixx="0.0478895372962598"
        ixy="-5.04435352663177E-14"
        ixz="-1.01430830053731E-13"
        iyy="0.0245109625270797"
        iyz="-1.20375931444983E-13"
        izz="0.0245109625268975" />
    </inertial>
    <visual>
      <origin
        xyz="0 0 0"
        rpy="0 0 0" />
      <geometry>
        <mesh
          filename="package://robot_simulation/meshes_robot2/Link_r.STL" />
      </geometry>
      <material
        name="">
        <color
          rgba="1 1 1 1" />
      </material>
    </visual>
    <collision>
      <origin
        xyz="0 0 0"
        rpy="0 0 0" />
      <geometry>
        <mesh
          filename="package://robot_simulation/meshes_robot2/Link_r.STL" />
      </geometry>
    </collision>
  </link>
  <joint
    name="joint_right"
    type="continuous">
    <origin
      xyz="0.0165000000000121 -0.0994999999999997 0.107999999999981"
      rpy="2.12103261147281 0 1.5707963267949" />
    <parent
      link="base_link" />
    <child
      link="Link_r" />
    <axis
      xyz="1 0 0" />
  </joint>

  <joint name="base_link2base_footprint" type="fixed">
      <parent link="base_footprint" />
      <child link="base_link"/>
      <origin xyz="0 0 0" rpy="0 0 0" />
  </joint>

  <link
    name="Link_l">
    <inertial>
      <origin
        xyz="-0.0544999999999977 6.80011602582908E-16 1.66533453693773E-15"
        rpy="0 0 0" />
      <mass
        value="2.8831968742214" />
      <inertia
        ixx="0.0478895372962598"
        ixy="-3.35632589915534E-13"
        ixz="2.24678912751338E-13"
        iyy="0.0245109625269403"
        iyz="1.17267306976032E-13"
        izz="0.024510962527037" />
    </inertial>
    <visual>
      <origin
        xyz="0 0 0"
        rpy="0 0 0" />
      <geometry>
        <mesh
          filename="package://robot_simulation/meshes_robot2/Link_l.STL" />
      </geometry>
      <material
        name="">
        <color
          rgba="1 1 1 1" />
      </material>
    </visual>
    <collision>
      <origin
        xyz="0 0 0"
        rpy="0 0 0" />
      <geometry>
        <mesh
          filename="package://robot_simulation/meshes_robot2/Link_l.STL" />
      </geometry>
    </collision>
  </link>
  <joint
    name="joint_left"
    type="continuous">
    <origin
      xyz="0.0165000000000123 0.208500000000001 0.107999999999981"
      rpy="2.80958859831297 0 1.5707963267949" />
    <parent
      link="base_link" />
    <child
      link="Link_l" />
    <axis
      xyz="1 0 0" />
  </joint>
  <link
    name="Link_base">
    <inertial>
      <origin
        xyz="1.41292850918941E-05 0.0602207038515709 -0.000603682453906879"
        rpy="0 0 0" />
      <mass
        value="0.571272620133457" />
      <inertia
        ixx="0.00101086034286069"
        ixy="4.56435228908895E-07"
        ixz="7.51494402259985E-08"
        iyy="0.00140801936985448"
        iyz="-1.32176903251832E-05"
        izz="0.00107590370416142" />
    </inertial>
    <visual>
      <origin
        xyz="0 0 0"
        rpy="0 0 0" />
      <geometry>
        <mesh
          filename="package://robot_simulation/meshes_robot2/Link_base.STL" />
      </geometry>
      <material
        name="">
        <color
          rgba="1 1 1 1" />
      </material>
    </visual>
    <collision>
      <origin
        xyz="0 0 0"
        rpy="0 0 0" />
      <geometry>
        <mesh
          filename="package://robot_simulation/meshes_robot2/Link_base.STL" />
      </geometry>
    </collision>
  </link>
  <joint
    name="j3"
    type="fixed">
    <origin
      xyz="0.230499999999998 0 0.164000000000002"
      rpy="1.5707963267949 0 1.5707963267949" />
    <parent
      link="base_link" />
    <child
      link="Link_base" />
    <axis
      xyz="0 0 0" />
  </joint>
  <link
    name="Link_1">
    <inertial>
      <origin
        xyz="0.00773427340425959 4.50102368609873E-06 -0.000904392326544823"
        rpy="0 0 0" />
      <mass
        value="1.79913629434417" />
      <inertia
        ixx="0.00328732296832481"
        ixy="-1.34887066748055E-07"
        ixz="0.00042035611051707"
        iyy="0.00353693990002428"
        iyz="1.37253652869673E-07"
        izz="0.00355851716430424" />
    </inertial>
    <visual>
      <origin
        xyz="0 0 0"
        rpy="0 0 0" />
      <geometry>
        <mesh
          filename="package://robot_simulation/meshes_robot2/Link_1.STL" />
      </geometry>
      <material
        name="">
        <color
          rgba="0.792156862745098 0.819607843137255 0.933333333333333 1" />
      </material>
    </visual>
    <collision>
      <origin
        xyz="0 0 0"
        rpy="0 0 0" />
      <geometry>
        <mesh
          filename="package://robot_simulation/meshes_robot2/Link_1.STL" />
      </geometry>
    </collision>
  </link>
  <joint
    name="joint_1"
    type="continuous">
    <origin
      xyz="0 0.162499992321044 0"
      rpy="-1.5707963267949 0 3.14159265358979" />
    <parent
      link="Link_base" />
    <child
      link="Link_1" />
    <axis
      xyz="0 0 -1" />
  </joint>
  <link
    name="Link_2">
    <inertial>
      <origin
        xyz="0.18919662210697 7.30049235786456E-07 -0.000838820208127644"
        rpy="0 0 0" />
      <mass
        value="5.27134064943703" />
      <inertia
        ixx="0.00780270591897656"
        ixy="-1.57632796218308E-07"
        ixz="0.000220475874243142"
        iyy="0.0240356175381961"
        iyz="8.96630385902477E-08"
        izz="0.0238605038791539" />
    </inertial>
    <visual>
      <origin
        xyz="0 0 0"
        rpy="0 0 0" />
      <geometry>
        <mesh
          filename="package://robot_simulation/meshes_robot2/Link_2.STL" />
      </geometry>
      <material
        name="">
        <color
          rgba="0.792156862745098 0.819607843137255 0.933333333333333 1" />
      </material>
    </visual>
    <collision>
      <origin
        xyz="0 0 0"
        rpy="0 0 0" />
      <geometry>
        <mesh
          filename="package://robot_simulation/meshes_robot2/Link_2.STL" />
      </geometry>
    </collision>
  </link>
  <joint
    name="joint_2"
    type="continuous">
    <origin
      xyz="0.140999992321044 0 0"
      rpy="-1.5707963267949 0 1.5707963267949" />
    <parent
      link="Link_1" />
    <child
      link="Link_2" />
    <axis
      xyz="0 0 -1" />
  </joint>
  <link
    name="Link_3">
    <inertial>
      <origin
        xyz="-0.0473482277540754 0.182811418653828 -3.25796184874605E-06"
        rpy="0 0 0" />
      <mass
        value="2.73044846910247" />
      <inertia
        ixx="0.0104071954582611"
        ixy="0.000143987338898576"
        ixz="-1.08390211671828E-07"
        iyy="0.00260693182304116"
        iyz="-4.34895775556025E-08"
        izz="0.0105662376264314" />
    </inertial>
    <visual>
      <origin
        xyz="0 0 0"
        rpy="0 0 0" />
      <geometry>
        <mesh
          filename="package://robot_simulation/meshes_robot2/Link_3.STL" />
      </geometry>
      <material
        name="">
        <color
          rgba="1 1 1 1" />
      </material>
    </visual>
    <collision>
      <origin
        xyz="0 0 0"
        rpy="0 0 0" />
      <geometry>
        <mesh
          filename="package://robot_simulation/meshes_robot2/Link_3.STL" />
      </geometry>
    </collision>
  </link>
  <joint
    name="joint_3"
    type="continuous">
    <origin
      xyz="0.427000000000004 0 0.0781999999999787"
      rpy="1.5707963267949 1.5707963267949 0" />
    <parent
      link="Link_2" />
    <child
      link="Link_3" />
    <axis
      xyz="1 0 0" />
  </joint>
  <link
    name="Link_4">
    <inertial>
      <origin
        xyz="0.019046811072364 2.62189913136091E-06 -0.00471201478266664"
        rpy="0 0 0" />
      <mass
        value="0.75307908796907" />
      <inertia
        ixx="0.000594720341853613"
        ixy="2.98869693743997E-09"
        ixz="0.000108276141881951"
        iyy="0.00101945654598876"
        iyz="1.22048328162273E-08"
        izz="0.000986591471542521" />
    </inertial>
    <visual>
      <origin
        xyz="0 0 0"
        rpy="0 0 0" />
      <geometry>
        <mesh
          filename="package://robot_simulation/meshes_robot2/Link_4.STL" />
      </geometry>
      <material
        name="">
        <color
          rgba="0.792156862745098 0.819607843137255 0.933333333333333 1" />
      </material>
    </visual>
    <collision>
      <origin
        xyz="0 0 0"
        rpy="0 0 0" />
      <geometry>
        <mesh
          filename="package://robot_simulation/meshes_robot2/Link_4.STL" />
      </geometry>
    </collision>
  </link>
  <joint
    name="joint_4"
    type="continuous">
    <origin
      xyz="0.0847000000000194 0.390499999999996 0"
      rpy="0 0 3.14159265358979" />
    <parent
      link="Link_3" />
    <child
      link="Link_4" />
    <axis
      xyz="1 0 0" />
  </joint>
  <link
    name="Link_5">
    <inertial>
      <origin
        xyz="0.0049594208984074 3.52152394400562E-06 -0.0061110253489752"
        rpy="0 0 0" />
      <mass
        value="0.580697784745691" />
      <inertia
        ixx="0.000463900738340175"
        ixy="2.81200098302899E-09"
        ixz="5.63283550867626E-05"
        iyy="0.000505896666156617"
        iyz="9.31887820468966E-09"
        izz="0.000479397456495676" />
    </inertial>
    <visual>
      <origin
        xyz="0 0 0"
        rpy="0 0 0" />
      <geometry>
        <mesh
          filename="package://robot_simulation/meshes_robot2/Link_5.STL" />
      </geometry>
      <material
        name="">
        <color
          rgba="0.792156862745098 0.819607843137255 0.933333333333333 1" />
      </material>
    </visual>
    <collision>
      <origin
        xyz="0 0 0"
        rpy="0 0 0" />
      <geometry>
        <mesh
          filename="package://robot_simulation/meshes_robot2/Link_5.STL" />
      </geometry>
    </collision>
  </link>
  <joint
    name="joint_5"
    type="continuous">
    <origin
      xyz="0 0 0.0965"
      rpy="3.14159265358979 1.5707963267949 0" />
    <parent
      link="Link_4" />
    <child
      link="Link_5" />
    <axis
      xyz="1 0 0" />
  </joint>
  <link
    name="Link_6">
    <inertial>
      <origin
        xyz="0.0231067452870509 -0.000150247579864704 -1.76864412004818E-10"
        rpy="0 0 0" />
      <mass
        value="0.178606321444053" />
      <inertia
        ixx="0.00012596796153639"
        ixy="-3.25478531435437E-07"
        ixz="-6.43552565190651E-13"
        iyy="8.80945714480635E-05"
        iyz="8.17331353372859E-13"
        izz="8.65449825290253E-05" />
    </inertial>
    <visual>
      <origin
        xyz="0 0 0"
        rpy="0 0 0" />
      <geometry>
        <mesh
          filename="package://robot_simulation/meshes_robot2/Link_6.STL" />
      </geometry>
      <material
        name="">
        <color
          rgba="0.792156862745098 0.819607843137255 0.933333333333333 1" />
      </material>
    </visual>
    <collision>
      <origin
        xyz="0 0 0"
        rpy="0 0 0" />
      <geometry>
        <mesh
          filename="package://robot_simulation/meshes_robot2/Link_6.STL" />
      </geometry>
    </collision>
  </link>
  <joint
    name="joint_6"
    type="continuous">
    <origin
      xyz="0 0 0.092"
      rpy="1.5707963267949 1.5707963267949 0" />
    <parent
      link="Link_5" />
    <child
      link="Link_6" />
    <axis
      xyz="1 0 0" />
  </joint>
</robot>